Workbook

Sheet README
A1: ATTORNEY WORK-PRODUCT SUPPORT — PREPARED FOR COUNSEL — NOT A FILING — NOT LEGAL ADVICE — DEMONSTRATIVE ARITHMETIC ONLY, NOT AN OPINION OF VALUE — DO NOT SEND TO ANY PARTY
A3: LEAL v. GARABEDIAN — SETTLEMENT MODEL
A4: Manuel Stephen Leal v. Ashley Garabedian, et al., Tulare County Superior Court
A5: Prepared August 18, 2026 for Brandon M. Ormonde, Ormonde Rascon
A7: PURPOSE
A8: Decomposes the gap between the two settlement positions and lets counsel test scenarios.
A9: Every stated figure is cited on the Sources tab. Both anchor columns tie to the actual letters.
A11: LEGEND
A12: BLUE text = hardcoded input (a stated/source figure, or a lever you may change)
A13: BLACK text = formula — do not overwrite
A14: YELLOW fill = key agreed figure or lever deserving attention
A16: HOW TO USE
... A33: - Open-ended claims NOT modeled unless entered: 2025 profit, BioGas/Feedstock credits, retains detail.

Sheet Inputs
A1: ATTORNEY WORK-PRODUCT SUPPORT — PREPARED FOR COUNSEL — NOT A FILING — NOT LEGAL ADVICE — DEMONSTRATIVE ARITHMETIC ONLY, NOT AN OPINION OF VALUE — DO NOT SEND TO ANY PARTY
A3: CUSTOM SCENARIO LEVERS (all blue cells editable — feed Model column E)
A6: Trust real-property share @100% value ($) | B6: 5725261.2 | C6: Midpoint illustration. Ours (Ex. R, CX basis): $5,334,797.50 · Theirs (Ex. U, avg basis): $6,115,725. See RealProperty tab.
A7: Minority interest discount (%) | B7: 0.2 | C7: Ours: 30% (Mar-25) then 25% (ME 7/2/25 + Jul-26 letter) · Theirs: 15% · Prior Xavier work: 20-30% (Complaint ¶17)
A8: Contractual buyout factor | B8: 0.9 | C8: Settlement Agmt ¶7(a)-(b); TIC; Pship Art. XIII.B.2 — 90% of appraised value
A9: Partnership value, trust 37.5% pre-90% ($) | B9: 1162612.5 | C9: AGREED per ME 7/2/25 (both columns identical): Moss $3,100,300 x 37.5%. Letters round to $1,162,875. See Partnership tab.
A11: Post-death compensation method (1=interest, 2=profit share) | B11: 1 | C11: THE contested legal question (Corp. Code s.16601 — UNVERIFIED). Contract prescribes 4% interest (Art. XIII.B.2).
A12: Interest rate | B12: 0.04 | C12: Art. XIII.B.2 / Settlement ¶7(b) note rate
A13: Interest start date | B13: 44827 | C13: Hazel's DOD. NOTE: our 7/2/26 letter figure implies a later start — see ProfitsInterest tab solver.
A14: Interest end date | B14: 46308 | C14: Placeholder = CMC date. Change to expected closing.
A16: Post-death profit share, 2022 stub 9/23-12/31 ($) | B16: 0 | C16: UNKNOWN — FY2022 statement does not split at DOD (pending FY2022 extract)
A17: Post-death profit share, FY2023 ($) | B17: -333228 | C17: FY2024/23 reviewed FS, Ex. C — Estate of Hazel Leal share of $(888,608) loss
A18: Post-death profit share, FY2024 ($) | B18: 759997 | C18: FY2024/23 reviewed FS, Ex. C
A19: Post-death profit share, FY2025 est. ($) | B19: 0 | C19: TBD — they reserved a 2025 claim
... A36: BioGas / Feedstock lease credits ($) | B36: 0 | C36: UNQUANTIFIED — not in any reviewed FS; their Ex. U item 5

Sheet Model
A1: ATTORNEY WORK-PRODUCT SUPPORT — PREPARED FOR COUNSEL — NOT A FILING — NOT LEGAL ADVICE — DEMONSTRATIVE ARITHMETIC ONLY, NOT AN OPINION OF VALUE — DO NOT SEND TO ANY PARTY
A3: SETTLEMENT MODEL — POSITION COMPARISON
C5: OUR POSITION | D5: THEIR POSITION | E5: CUSTOM | F5: Notes
C6: ltr 7/2/2026 | D6: ltr 6/19/2025 | E6: from Inputs tab
A8: Real property — trust interest, discounted, pre-90% ($) | C8: n/a — letter states post-90% only | D8: 5198366 | E8: =Inputs!B6*(1-Inputs!B7) -> 4580209 | F8: Their schedule: $6,115,725 less 15% (RealProperty tab)
A9: Partnership — trust interest, discounted, pre-90% ($) | C9: n/a | D9: 1162875 | E9: =Inputs!B9 -> 1162612.5 | F9: AGREED NUMBER — identical on both sides per ME 7/2/25 (Partnership tab)
A11: Real property buyout price (post-90%) | C11: 3653412.5 | D11: =D8*0.9 -> 4678529.4 | E11: =E8*Inputs!B8 -> 4122188.1 | F11: Our stated figure is a PLUG to reach a round $4.7M — computed value is $3,600,988.31 (RealProperty tab)
A12: Partnership buyout price (post-90%) | C12: 1046587.5 | D12: =D9*0.9 -> 1046587.5 | E12: =E9*Inputs!B8 -> 1046351.2
A13: Buyout subtotal | C13: =SUM(C11:C12) -> 4700000 | D13: =SUM(D11:D12) -> 5725116.9 | E13: =SUM(E11:E12) -> 5168539.3 | F13: Ours = exactly $4,700,000 · Theirs = $5,725,116.90 (letter says $5,725,117)
A15: Pre-death profit claim (net) | C15: 0 | D15: inside bundle below | E15: =Inputs!B25*(Inputs!B22+Inputs!B23-Inputs!B24) -> 850894.54 | F15: Ours: 0 — released/subsumed; note $850,894.54 was AGREED 8/30/2022 on annual, basis-capped terms
A16: Post-death compensation — 4% interest | C16: 677830.41 | D16: 0 | E16: =IF(Inputs!B11=1,(E11+E12)*Inputs!B12*YEARFRAC(Inputs!B13,Inputs!B14,1),0) -> 838401.62 | F16: Ours implies a ~Nov 2022 start (ProfitsInterest solver). Custom: base = buyout subtotal, simplification of the note structure
A17: Post-death compensation — profit share | C17: 0 | D17: inside bundle below | E17: =IF(Inputs!B11=2,IF(Inputs!B20=1,Inputs!B16+Inputs!B17+Inputs!B18+Inputs!B19,MAX(0,Inputs!B16)+MAX(0,Inputs!B17)+MAX(0,Inputs!B18)+MAX(0,Inputs!B19)),0) -> 0 | F17: FY23 estate share $(333,228) + FY24 $759,997 = net $426,769 (ProfitsInterest tab)
A18: Their profit + interest bundle ("$1,617,761") | C18: 0 | D18: 1617761 | E18: 0 | F18: → $1,498,480 accrued profit + $119,281 accrued interest exactly (me 7/2/25; profitsinterest tab). spans pre- and post-death.
A19: Bypass Trust income through DOD | C19: 327427.02 | D19: inside bundle | E19: =Inputs!B28*Inputs!B27 -> 0 | F19: DOUBLE-COUNT flag: $262,592 offset already credits $329,373 of Bypass income (CapitalRecon)
A20: One-half appraisal & valuation fees | C20: 0 | D20: 16888 | E20: =Inputs!B35 -> 0 | F20: The previously "unexplained" $16,888 in their total — identified by ME as one-half fees
A21: Offsets (excess draws; post-death draws) | C21: 0 | D21: 0 | E21: =-Inputs!B32*(Inputs!B30+Inputs!B31) -> -456945 | F21: Ours WAIVED in the 7/2/26 offer (see Bridge). Support: Frazer recon (CapitalRecon tab)
A22: Retains / BioGas / 2025 profit (TBD items) | C22: 0 | D22: 0 | E22: =Inputs!B34+Inputs!B36 -> 0 | F22: Their letter reserves 2025 profit + BioGas/Feedstock credits ON TOP of $7,359,766 — unquantified
A24: COMPUTED TOTAL | C24: =SUM(C13,C15:C22) -> 5705257.4 | D24: =SUM(D13,D15:D22) -> 7359765.9 | E24: =SUM(E13,E15:E22) -> 6400890.5
A25: STATED TOTAL per letter | C25: 5705257.4 | D25: 7359766
A26: Tie-out variance (computed - stated) | C26: =C24-C25 -> 0 | D26: =D24-D25 -> -0.1 | F26: Ours ties to $0.00; theirs to -$0.10 (their rounding)
A28: GAP (Their computed - Our computed) | D28: =D24-C24 -> 1654508.5
A29: Custom vs Our / vs Their | C29: =E24-C24 -> 695633.08 | D29: =E24-D24 -> -958875.39
A32: BRIDGE — from Mike Edwards' 7/2/2025 model to the two letters (exact)
A34: ME model — Steve-side bottom line (25% disc, offsets taken) | C34: 4190394.6 | F34: ME Revised 7-2-25, cell O52
A35: + Round-up plug to $4,700,000 principal | C35: =4700000-(3600988.3125+1046351.25) -> 52660.438 | F35: → $52,660.44 (rp $52,424.19 + pship $236.25 — RealProperty tab))
A36: + Offsets waived (262,592 + 194,353) | C36: =262592+194353 -> 456945 | F36: Waiver is INSIDE the round $4.7M: 4,190,394.56+52,660.44+456,945 = 4,700,000.00
A37: + Bypass income added | C37: 327427.02
A38: + 4% interest added | C38: 677830.41
A39: → our 7/2/2026 offer (exact) | C39: =SUM(C34:C38) -> 5705257.4 | F39: Ties to $5,705,257.43 to the penny
A41: ME model — Hazel-side bottom line | C41: 7359529.9 | F41: ME Revised 7-2-25, cell J52
A42: + Their letter rounding | C42: =7359766-C41 -> 236.125 | F42: → $236.13
A43: → their 6/19/2025 demand | C43: =C41+C42 -> 7359766
A46: GAP DECOMPOSITION (per ME 7/2/2025, "Difference" column)
A48: Real property (basis + discount, combined) | C48: 1077541.3 | F48: ME R18 — the two RP levers together
A49: Partnership value | C49: 0 | F49: AGREED — zero difference
A50: Accrued profit distributions (their method) | C50: 1498480 | F50: ME R47
A51: Net capital adjustment thru 9/22/22 (our offset) | C51: 262592 | F51: ME R48
A52: Post-death draws 9/22/22-1/16/25 (our offset) | C52: 194353 | F52: ME R49
A53: Accrued interest (their claim) | C53: 119281 | F53: ME R50
A54: One-half appraisal & valuation fees | C54: 16888 | F54: ME R51
...

Sheet RealProperty
A1: ATTORNEY WORK-PRODUCT SUPPORT — PREPARED FOR COUNSEL — NOT A FILING — NOT LEGAL ADVICE — DEMONSTRATIVE ARITHMETIC ONLY, NOT AN OPINION OF VALUE — DO NOT SEND TO ANY PARTY
A3: REAL PROPERTY — BOTH SCHEDULES, LINE BY LINE
A5: THEIR SCHEDULE (Ex. U, 6/19/2025 letter)
A6: Correia-Xavier appraisal (8/8/2023) | B6: 14220000 | E6: both appraisals valued as of 9/22/2022 per Moss Adams (one day BEFORE DOD — flag)
A7: J. Hower appraisal (12/13/2023) | B7: 18100000
A8: Average (their basis) | B8: =AVERAGE(B6:B7) -> 16160000 | E8: → $16,160,0
A9: Less APN 158-160-006 (100% Hazel parcel) | B9: -193400
A10: Plus APN 158-150-004 (1.49 ac, JHA/avg value) | B10: 35760 | E10: NB: ME Steve-side uses $20,860 (CX value) for this parcel
A11: Net basis | B11: =SUM(B8:B10) -> 16002360 | E11: → $16,2,360
A12: 50% x APN 158-160-005 ($918,720) | B12: =918720*0.5 -> 459360
A13: 37.5% x remaining ($15,083,640) | B13: =(B11-918720)*0.375 -> 5656365
A14: Trust share subtotal | B14: =B12+B13 -> 6115725 | E14: → $6,115,725
A15: Less 15% minority discount | B15: =-B14*0.15 -> -917358.75
A16: Discounted trust value | B16: =B14+B15 -> 5198366.2 | E16: → $5,198,366.25 (letter: $5,198,366)
A17: x 90% buyout factor | B17: =B16*0.9 -> 4678529.6 | E17: → $4,678,529.63
A20: OUR SCHEDULE (Ex. R, 3/3/2025 letter — CX basis)
A21: CX dairy land improvements | B21: 2410000
A22: CX dairy land net of improvements | B22: 5804000
A23: APN 158-150-004 (1.49 ac, CX value) | B23: 20860
A24: Less APN 158-160-006 (100% Hazel) | B24: -193400
A25: Subtotal | B25: =SUM(B21:B24) -> 8041460 | E25: → $8,41,460
A26: APN 158-160-005 | B26: 536000
A27: Almonds | B27: 960000
A28: Pistachios | B28: 2790000
A29: Feedlot incl. improvements | B29: 1720000
A30: Total land value @100% | B30: =SUM(B25:B29) -> 14047460 | E30: → $14,47,460
A31: Trust share: 37.5% of most + 50% of 158-160-005 | B31: =(B30-B26)*0.375+B26*0.5 -> 5334797.5 | E31: → $5,334,797.5
A32: Less 30% discount (March 2025 position) | B32: =B31*0.7 -> 3734358.2 | E32: → $3,734,358.25
A33: x 90% (March 2025 offer RP component) | B33: =B32*0.9 -> 3360922.4 | E33: → $3,360,922.43
A34: At 25% discount (ME 7/2/25 + July 2026 position) | B34: =B31*0.75*0.9 -> 3600988.3 | E34: → $3,600,988.31
A37: JULY 2026 LETTER RECONCILIATION — the "$4.7M is a rounded plug" proof
A38: Computed RP at 25%/90% (above) | B38: =B34 -> 3600988.3 | E38: $3,600,988.31
A39: Computed partnership (Partnership tab) | B39: 1046351.2 | E39: → $1,162,612.5 x 90%
A40: Computed principal | B40: =B38+B39 -> 4647339.6 | E40: → $4,647,339.56
A41: Stated principal (7/2/2026 letter) | B41: 4700000
A42: Round-up plug | B42: =B41-B40 -> 52660.438 | E42: → $52,660.44
A43: of which: RP allocation plug | B43: =3653412.5-B38 -> 52424.188 | E43: → $52,424.19 (stated $3,653,412.5)
A44: of which: partnership allocation plug | B44: =1046587.5-B39 -> 236.25 | E44: → $236.25 (stated $1,46,587.5)
A45: Check: plugs sum to round-up | B45: =B43+B44-B42 -> 0 | E45: → $0.00

Sheet Partnership
A1: ATTORNEY WORK-PRODUCT SUPPORT — PREPARED FOR COUNSEL — NOT A FILING — NOT LEGAL ADVICE — DEMONSTRATIVE ARITHMETIC ONLY, NOT AN OPINION OF VALUE — DO NOT SEND TO ANY PARTY
A3: PARTNERSHIP — THE AGREED NUMBER AND ITS DERIVATION (per ME 7/2/2025; both sides identical)
B5: Moss Adams as issued | C5: Remove bldgs/impr | D5: Revised
A6: Adjusted book value (Ex. 15, asset approach) | B6: 12582000 | C6: -7432000 | D6: =B6+C6 -> 5150000 | E6: $7,432,000 of buildings/improvements were ALSO in the real estate appraisal — double-count removed (agreed)
A7: Less 14% discount for control | B7: =-B6*0.14 -> -1761480 | C7: =-C6*0.14 -> 1040480 | D7: =-D6*0.14 -> -721000
A8: Indicated value | B8: =B6+B7 -> 10820520 | C8: =C6+C7 -> -6391520 | D8: =D6+D7 -> 4429000
A9: Plus interest-bearing debt | B9: 3885000 | D9: =B9 -> 3885000
A10: Asset-approach value | B10: =B8+B9 -> 14705520 | D10: =D8+D9 -> 8314000
A11: Less interest-bearing debt | B11: =-B9 -> -3885000 | D11: =-D9 -> -3885000
A12: Concluded equity | B12: =B10+B11 -> 10820520 | D12: =D10+D11 -> 4429000
A13: Less 30% DLOM | B13: =-B12*0.3 -> -3246156 | D13: =-D12*0.3 -> -1328700
A14: Equity, non-marketable | B14: =B12+B13 -> 7574364 | D14: =D12+D13 -> 3100300 | E14: ME: $3,100,300 · our letters used "$3,101,000" (rounding)
A15: x 37.5% trust interest | B15: =B14*0.375 -> 2840386.5 | D15: =D14*0.375 -> 1162612.5 | E15: Moss as issued: $2,840,386.50 (letters: $2,840,000) · Revised: $1,162,612.50 (letters: $1,162,875)
A16: x 90% buyout factor | B16: =B15*0.9 -> 2556347.9 | D16: =D15*0.9 -> 1046351.2 | E16: Revised: $1,046,351.25 (letters: $1,046,587.50)

Sheet ProfitsInterest
A1: ATTORNEY WORK-PRODUCT SUPPORT — PREPARED FOR COUNSEL — NOT A FILING — NOT LEGAL ADVICE — DEMONSTRATIVE ARITHMETIC ONLY, NOT AN OPINION OF VALUE — DO NOT SEND TO ANY PARTY
A3: POST-DEATH COMPENSATION AND THE PROFIT CLAIM — BOTH FRAMEWORKS
A5: A. THEIR $1,617,761 — EXACT DECOMPOSITION (ME 7/2/2025)
A6: Accrued profit distributions (through Dec 2024) | B6: 1498480 | D6: Trajectory: $850,894.54 agreed for 2015-2021 (8/30/22 email) -> $1,498,480 thru 2024 -> increment for 2022-2024 = formula right
A7: Accrued interest | B7: 119281 | D7: Basis of their interest computation not stated — request it
A8: Sum | B8: =B6+B7 -> 1617761
A9: Their letter figure | B9: 1617761
A10: Variance | B10: =B8-B9 -> 0 | D10: → $0 — exact
A11: Implied 2022-2024 increment over agreed 2015-21 | B11: =B6-850894.54 -> 647585.46 | D11: → $647,585.46 — test against FY2023 LOSS: estate share was $(333,228); demand whether their accrual nets losses
A13: B. THE AGREED BASELINE — 8/30/2022 EMAIL (24 days before DOD)
A14: Agreed profit due Hazel + Hazel-as-Bypass-beneficiary, 2015-2021 | B14: 850894.54 | D14: Esraelian: "agree with YOUR calculation". Terms: ANNUAL distributions capped at Hazel/Bypass basis, via Mike Edwards, to avoid capital gains. Pull native email + thread (133 mailbox hits).
A16: C. OUR CAPITAL-PARITY FRAMEWORK (Frazer recon rev. 2/13/2025 — CapitalRecon tab)
A17: Hazel excess draws vs 37.5% capital parity, thru 9/22/22 | B17: -591965 | D17: (she drew above her share)
A18: Bypass Trust income due (net of draws), Manuel DOD -> Hazel DOD | B18: 329373 | D18: credited to her
A19: → hazel net excess (the $262,592 offset) | B19: =B17+B18 -> -262592 | D19: ties: $(262,592)
A20: Post-death draws to her side 9/22/22 - 1/16/25 | B20: -194353 | D20: second offset
A21: DOUBLE-COUNT FLAG: our offer separately adds Bypass income of | B21: 327427.02
A22: vs the $329,373 already credited inside the offset — difference | B22: =329373-B21 -> 1945.98 | D22: RESOLVED 8/18/2026 (trust-admin sweep): they ARE the same figure — Appraisal Summary 1.22.25.xlsx "Bypass Income" sheet shows $329,373 less $1,945 of 2022 Bypass draws = $327,427.02 EXACTLY. The offset credits it once and the offer pays it again. Also: the Bypass Trust's own 1041s (2015-2019, Hazel as trustee) report NEGATIVE income, $0 DNI, "NO REPORTABLE INCOME" K-1s. Frazer must resolve whether credit and payment run through different accounts before any number is reused. See adverse analysis A-55 / OI-60; trust-admin-sweep.md sec.3.4.
A24: D. POST-DEATH PROFIT SHARE PER OUR OWN REVIEWED FS
A25: 2022 stub 9/23-12/31 (unknown — FS does not split) | B25: 0
A26: FY2023 — Estate of Hazel Leal share of $(888,608) loss | B26: -333228
A27: FY2024 — Estate share of $2,026,658 income | B27: 759997
A28: FY2025 (TBD) | B28: 0
A29: Net post-death allocation per books (losses included) | B29: =SUM(B25:B28) -> 426769 | D29: → $426,769 — far below their accrual; if she shares profits she shares losses
A31: E. INTEREST — OUR FIGURE AND ITS IMPLIED DATES
A32: Stated interest, 7/2/2026 letter | B32: 677830.41
A33: Base (stated principal) | B33: 4700000
A34: Rate | B34: 0.04
A35: Implied years = interest/(base x rate) | B35: =B32/(B33*B34) -> 3.6054809 | D35: ~3.61 years
A36: RESOLVED 8/18/2026: 4% on $4.7M, DOD start, computed only THROUGH 5/1/2026 | B36: =B33*B34*(DATE(2026,5,1)-DATE(2022,9,23))/365 -> 677830.14 | D36: → computes $677,830.14 vs stated $677,830.41 (27 cents apart). Figure FIRST APPEARS in 5/1/2026 internal draft labeled "through May 1, 2026" and was reused verbatim in the 5/4 drafts, the 5/18 $5.75M letters, and the 7/2/2026 letter. See drive-sweep/drafts-proposals-sweep.md, item C-7. The earlier "implied start ~Nov 2022" reading is superseded.
A37: What a FRESH computation through 7/2/2026 would give (same formula) | B37: =B33*B34*YEARFRAC(DATE(2022,9,23),DATE(2026,7,2),1) -> 709375.68 | D37: ~ $709,395 — what a DOD start would give
A38: Difference (DOD start - stated) | B38: =B37-B32 -> 31545.275
A39: Consequence | D39: → Under our own stated formula the 7/2/2026 offer under-credits interest by ~$31.9K (stale by 62 days). Refresh the interest figure before any renewed offer; opposing counsel can use the staleness to argue the number is negotiated, not contract math.

Sheet CapitalRecon
A1: ATTORNEY WORK-PRODUCT SUPPORT — PREPARED FOR COUNSEL — NOT A FILING — NOT LEGAL ADVICE — DEMONSTRATIVE ARITHMETIC ONLY, NOT AN OPINION OF VALUE — DO NOT SEND TO ANY PARTY
A3: FRAZER CAPITAL RECONCILIATION 3/25/2015 - 9/22/2022 (rev. 2/13/2025 — DRAFT, FOR INTERNAL DISCUSSION ONLY)
A4: P&L percentages 37.5% Hazel / 55% Steve / 7.5% Bypass. Opening balances derive from the 75/25 historical split.
B6: Total | C6: Hazel Leal | D6: Steve Leal | E6: Bypass Trust
A7: 3/25/2015 beginning balance | B7: 5041721 | C7: 1925995 | D7: 2730527 | E7: 385199 | F7: Opening = 75/25 transfer basis (matches 2017 Capital Analysis 75/25 scenario)
A8: 2015: contributions | B8: 346052 | C8: 88026 | D8: 258026 | E8: 0
A9: 2015: net income | B9: 283908 | C9: 106465 | D9: 156149 | E9: 21293
A10: 2015: distributions | B10: -190800 | C10: -111773 | D10: -79027 | E10: 0
A11: 12/31/2015 balance | B11: 5480881 | C11: 2008714 | D11: 3065675 | E11: 406492 | F11: PDF mislabels this line "12/31/2016" — typo. Total differs from reviewed FS ($5,478,612) by $2,269 (futures item)
A12: 2016: net income (loss) | B12: -214285 | C12: -80357 | D12: -117857 | E12: -16071
A13: 2016: distributions | B13: -297218 | C13: -161211 | D13: -83626 | E13: -52381
A14: 12/31/2016 balance | B14: 4969378 | C14: 1767146 | D14: 2864192 | E14: 338040
A15: 2017: contributions | B15: 60000 | C15: 0 | D15: 60000 | E15: 0
A16: 2017: net income | B16: 1020069 | C16: 382526 | D16: 561038 | E16: 76505
A17: 2017: distributions | B17: -276229 | C17: -180065 | D17: -64201 | E17: -31963
A18: 12/31/2017 balance | B18: 5773218 | C18: 1969607 | D18: 3421029 | E18: 382582
A19: 2018: contributions | B19: 93630 | C19: 0 | D19: 93630 | E19: 0
A20: 2018: net income | B20: 576611 | C20: 216229 | D20: 317136 | E20: 43246
A21: 2018: distributions | B21: -434875 | C21: -200566 | D21: -230109 | E21: -4200
A22: 12/31/2018 balance | B22: 6008584 | C22: 1985270 | D22: 3601686 | E22: 421628
A23: 2019: net income | B23: 1321713 | C23: 495642 | D23: 726942 | E23: 99128
... A35: 2022: distributions (to 9/22) | B35: -284904 | C35: -158642 | D35: -126262 | E35: 0
A36: 9/22/2022 CAPITAL | B36: 8894165 | C36: 2743347 | D36: 5356246 | E36: 794572 | F36: Actual mix: 30.84% / 60.22% / 8.93%
A38: Target at 37.5 / 55 / 7.5 | B38: =B36 -> 8894165 | C38: =$B36*0.375 -> 3335311.9 | D38: =$B36*0.55 -> 4891790.8 | E38: =$B36*0.075 -> 667062.38
A39: (Excess draws) / amount receivable | B39: =B36-B38 -> 0 | C39: =C36-C38 -> -591964.88 | D39: =D36-D38 -> 464455.25 | E39: =E36-E38 -> 127509.62 | F39: Hazel $(591,965) / Steve $464,455 / Bypass $127,509
A41: Bypass: PY adj + net income - draws (Manuel DOD -> Hazel DOD) | B41: =2079+418023-90729 -> 329373 | F41: → $329,373
A42: HAZEL NET EXCESS (the offset) | B42: =C39+B41 -> -262591.88 | F42: → $(262,592) — the figure in the 3/3/2025 letter and ME model
A44: Memo: cash distributed to Hazel 3/25/2015-9/22/2022 | B44: =-(C10+C13+C17+C21+C24+C29+C32+C35) -> 1371182 | F44: Her column distributions summed = $1,371,182 — rebuts "she received nothing"; the dispute is characterization

Sheet Sources
A1: ATTORNEY WORK-PRODUCT SUPPORT — PREPARED FOR COUNSEL — NOT A FILING — NOT LEGAL ADVICE — DEMONSTRATIVE ARITHMETIC ONLY, NOT AN OPINION OF VALUE — DO NOT SEND TO ANY PARTY
A3: SOURCES FOR EVERY HARDCODED FIGURE
A5: Our 7/2/2026 offer figures ($3,653,412.50 / $1,046,587.50 / $4,700,000 / $327,427.02 / $677,830.41 / $5,705,257.43) | B5: 2026-7-2 BMO Atty Cunningham Ltr.pdf (Drive 1nnHz4PJtMz7wv-6b1GGwpV-0CT7Xq4we)
A6: Their 6/19/2025 figures ($5,198,366 / $1,162,875 / $5,725,117 / $1,617,761 / $7,359,766) and RP schedule | B6: Ex. U to Complaint (in defendants' mediation brief PDF, Drive 1BD14JDeC0VTQGemgiFgWkjmDG-kmo7ly)
A7: Our 3/3/2025 schedule (CX basis $14,047,460; share $5,334,797.50; 30%; $3,950,565.28; offsets $262,592 / $194,352.65) | B7: Ex. R to Complaint (same PDF)
A8: ME reconciliation (both columns; $1,498,480; $119,281; $16,888; $4,190,394.56; $7,359,529.88; 25% discount; partnership $1,162,612.50) | B8: ME_analysis_of_appraisals_722025.xlsx, tab "ME Revised 7-2-25" (client-provided 8/18/2026; author understood to be Mike Edwards, Frazer LLP) — WORK PRODUCT, do not produce inadvertently
A9: Frazer capital reconciliation (all CapitalRecon figures; $591,965; $329,373; $262,592) | B9: Financial_Statement_Capital_thru_Hazels_DOD_revised_2132025.pdf (client-provided 8/18/2026) — marked DRAFT - FOR INTERNAL DISCUSSION PURPOSES ONLY; likely Ex. B to the 3/3/2025 letter
A10: $850,894.54 agreed, 2015-2021, annual/basis-capped terms | B10: Email, R. Esraelian to J. Leal & L. Garabedian Ruff, cc S. Leal, 8/30/2022 — transcribed from client screenshot; PULL NATIVE EMAIL
A11: FY2023/FY2024 estate allocations ($(333,228) / $759,997), withdrawals, Note 8 Bypass transfer | B11: Manuel Leal & Son Dairy 12.31.2024 FS (Frazer review 2/18/2025), Drive 1cqN3Cp2t9pMFiql2mXOYYZFZTxsSVZRm, Ex. C
A12: Moss Adams appraisal review (both credible; no obvious errors; recommends averaging or third appraiser) | B12: Ex. Q to Complaint — Steven A. Klett, MAI, 9/10/2024 — marked FOR CLIENT USE ONLY / NOT TO BE RELIED UPON BY THIRD PARTIES
A13: 90% buyout, 4% note, three-appraiser fallback, death = Dissociating Event | B13: Settlement Agreement ¶7; Amended Partnership Agreement Art. XIII.B.1-2, J (Exs. A & C to defendants' brief)
A14: Contested legal premise: post-death profit vs. dissociation + interest | B14: UNVERIFIED — Corp. Code s.16601/16603/16701 could not be retrieved in this environment; counsel must verify (workspace OI-30)
A15: Internal drafts corpus: "Leal Trust/Partnership" Drive folder (23 files) + "Land Acquisition" (3 files), all read 8/18/2026 | B15: Per-file Drive IDs and extracts: cmc-prep/01-verified-facts/drive-sweep/drafts-proposals-sweep.md. NOTE: internal AI-generated drafts — figures therein are NOT positions of record; used here only to source the C-7 interest-staleness finding and offset-stack history.
